Workbook

Sheet 01_Instructions
A1: TEMPLATE D'ÉVALUATION COMPARATIVE — SIEM & NAC (3 OFFRES)
A4: Objectif | B4: Comparer objectivement trois offres techniques pour l'acquisition d'un SIEM et d'un NAC, avec notation pondérée et TCO.
A5: Mode d'emploi
A6: 1 | B6: Remplir la feuille 02_Contexte : votre périmètre, contraintes et pondérations (poids des critères).
A7: 2 | B7: Identifier les 3 soumissionnaires dans 02_Contexte (Offre A / B / C).
A8: 3 | B8: Compléter 03_SIEM_Critères et 04_NAC_Critères : réponse Oui/Partiel/Non + note 0–5 + commentaire.
A9: 4 | B9: Saisir les coûts dans 05_TCO (licence, déploiement, support, stockage, formation…).
A10: 5 | B10: Consulter 06_Scores (calculs automatiques) et 07_Synthese pour la recommandation.
A12: Échelle de notes
A13: 0 | B13: Absent / non conforme
A14: 1 | B14: Très insuffisant
A15: 2 | B15: Insuffisant / écarts majeurs
A16: 3 | B16: Acceptable / écarts mineurs
A17: 4 | B17: Bon / conforme au besoin
A18: 5 | B18: Excellent / dépasse le besoin
A20: Couleurs
A21: Jaune | B21: Cellules à remplir (saisie manuelle)
A22: Vert | B22: Cellules calculées automatiquement — ne pas modifier
A24: Conseil | B24: Adaptez les poids dans 02_Contexte pour refléter vos priorités (ex. : conformité, TCO, intégration AD, SOC 24/7).
B25: Conservez une trace des preuves (références pages de l'offre) dans la colonne Commentaire.

Sheet 02_Contexte
A1: CONTEXTE & PÉRIMÈTRE D'ACQUISITION
A3: IDENTIFICATION DES OFFRES
A4: Champ | B4: Offre A | C4: Offre B | D4: Offre C | E4: Commentaire
A5: Nom éditeur / produit SIEM
A6: Nom éditeur / produit NAC
A7: Intégrateur / revendeur
A8: Référence proposition
A9: Date de l'offre
A10: Validité de l'offre
A11: Contact commercial
A12: Modèle de déploiement (On-prem / SaaS / Hybride)
A14: PÉRIMÈTRE TECHNIQUE (à renseigner une seule fois)
A15: Paramètre | B15: Valeur | C15: Unité | D15: Obligation (O/S) | E15: Notes
A16: Nombre d'utilisateurs / identités | C16: u | D16: O
A17: Nombre d'endpoints (EPS) SIEM | C17: EPS | D17: O
A18: Volume de logs / jour estimé | C18: Go/jour | D18: O
A19: Durée de rétention chaude | C19: jours | D19: O
A20: Durée de rétention froide / archive | C20: mois | D20: S
A21: Nombre de sites / datacenters | C21: sites | D21: O
A22: Nombre de switches / contrôleurs Wi-Fi (NAC) | C22: équip. | D22: O
A23: Couverture Wi-Fi / filaire / VPN / IoT | C23: texte | D23: O
A24: Intégration AD / Entra ID / LDAP | C24: Oui/Non | D24: O
A25: Exigence Haute Disponibilité | C25: Oui/Non | D25: S
A26: Exigence hébergement données (UE / souveraineté) | C26: texte | D26: O
A27: SOC interne / MSSP / hybride | C27: texte | D27: O
... A29: Date cible de mise en production | C29: date | D29: S
A32: PONDÉRATION DES CRITÈRES SIEM (total = 100 %)
A33: Famille de critères | B33: Poids % | C33: Offre A (auto) | D33: Offre B (auto) | E33: Offre C (auto)
A34: Fonctionnalités & détection | B34: 25 | C34: → voir 06_Scores | D34: → voir 06_Scores | E34: → voir 06_Scores
A35: Architecture & performance | B35: 15 | C35: → voir 06_Scores | D35: → voir 06_Scores | E35: → voir 06_Scores
A36: Intégrations & écosystème | B36: 15 | C36: → voir 06_Scores | D36: → voir 06_Scores | E36: → voir 06_Scores
A37: Exploitation & usabilité SOC | B37: 15 | C37: → voir 06_Scores | D37: → voir 06_Scores | E37: → voir 06_Scores
A38: Sécurité, conformité, gouvernance | B38: 10 | C38: → voir 06_Scores | D38: → voir 06_Scores | E38: → voir 06_Scores
A39: Support, formation, roadmap | B39: 10 | C39: → voir 06_Scores | D39: → voir 06_Scores | E39: → voir 06_Scores
A40: TCO / rapport qualité-prix | B40: 10 | C40: → voir 06_Scores | D40: → voir 06_Scores | E40: → voir 06_Scores
A41: TOTAL poids SIEM | B41: =SUM(B34:B40)
B42: Le total doit être égal à 100
A44: PONDÉRATION DES CRITÈRES NAC (total = 100 %)
A45: Famille de critères | B45: Poids % | C45: Offre A (auto) | D45: Offre B (auto) | E45: Offre C (auto)
A46: Contrôle d'accès & politiques | B46: 25 | C46: → voir 06_Scores | D46: → voir 06_Scores | E46: → voir 06_Scores
...

Sheet 03_SIEM_Critères
A1: GRILLE D'ÉVALUATION TECHNIQUE — SIEM
A2: Remplir les colonnes jaunes. Conformité = Oui / Partiel / Non / N/A. Note = 0 (absent) à 5 (excellent). Les totaux sont dans 06_Scores.
A3: Critère | B3: Famille | C3: A — Conformité | D3: A — Note (0-5) | E3: A — Commentaire | F3: B — Conformité | G3: B — Note (0-5) | H3: B — Commentaire | I3: C — Conformité | J3: C — Note (0-5) | K3: C — Commentaire | L3: Preuve / réf. offre
A4: FONCTIONNALITÉS & DÉTECTION
A5: Collecte multi-sources (syslog, agents, API, cloud) | B5: Fonctionnalités & détection
A6: Corrélation temps réel / règles custom | B6: Fonctionnalités & détection
A7: UEBA / détection comportementale / ML | B7: Fonctionnalités & détection
A8: Threat intelligence intégrée (feeds) | B8: Fonctionnalités & détection
A9: SOAR / playbooks / automatisation | B9: Fonctionnalités & détection
A10: Cas d'usage métiers pré-packagés | B10: Fonctionnalités & détection
A11: Recherche forensics / hunting | B11: Fonctionnalités & détection
A12: Tableaux de bord & reporting (KPI, conformité) | B12: Fonctionnalités & détection
A13: ARCHITECTURE & PERFORMANCE
A14: Scalabilité (EPS / volume) | B14: Architecture & performance
A15: Haute disponibilité / PRA-PCA | B15: Architecture & performance
A16: Rétention chaude / froide / archive | B16: Architecture & performance
A17: Latence d'ingestion & alerting | B17: Architecture & performance
A18: Architecture On-prem / SaaS / hybride proposée | B18: Architecture & performance
A19: INTÉGRATIONS & ÉCOSYSTÈME
A20: Intégration AD / Entra ID / IAM | B20: Intégrations & écosystème
A21: Intégration EDR / XDR / antivirus | B21: Intégrations & écosystème
A22: Intégration firewall / proxy / mail gateway | B22: Intégrations & écosystème
A23: Intégration ticketing (ServiceNow, Jira…) | B23: Intégrations & écosystème
A24: Intégration avec le NAC (événements / politiques) | B24: Intégrations & écosystème
A25: Connecteurs cloud (M365, AWS, Azure, GCP) | B25: Intégrations & écosystème
A26: EXPLOITATION & USABILITÉ SOC
A27: Ergonomie console / courbe d'apprentissage | B27: Exploitation & usabilité SOC
A28: Gestion des faux positifs / tuning | B28: Exploitation & usabilité SOC
A29: RBAC / multi-tenancy / équipes | B29: Exploitation & usabilité SOC
A30: Charge d'administration estimée | B30: Exploitation & usabilité SOC
A31: Documentation & contenu (règles, parsers) | B31: Exploitation & usabilité SOC
A32: SÉCURITÉ, CONFORMITÉ, GOUVERNANCE
A33: Chiffrement données au repos / en transit | B33: Sécurité, conformité, gouvernance
A34: Hébergement / souveraineté des données | B34: Sécurité, conformité, gouvernance
A35: Traçabilité admin / audit trail | B35: Sécurité, conformité, gouvernance
A36: Conformité (RGPD, ISO 27001, NIS2, secteur) | B36: Sécurité, conformité, gouvernance
A37: SUPPORT, FORMATION, ROADMAP
A38: SLA support (horaires, sévérités) | B38: Support, formation, roadmap
A39: Formation incluse / transfert de compétences | B39: Support, formation, roadmap
A40: Roadmap produit & pérennité éditeur | B40: Support, formation, roadmap
...

Sheet 04_NAC_Critères
A1: GRILLE D'ÉVALUATION TECHNIQUE — NAC
A2: Remplir les colonnes jaunes. Conformité = Oui / Partiel / Non / N/A. Note = 0 (absent) à 5 (excellent). Les totaux sont dans 06_Scores.
A3: Critère | B3: Famille | C3: A — Conformité | D3: A — Note (0-5) | E3: A — Commentaire | F3: B — Conformité | G3: B — Note (0-5) | H3: B — Commentaire | I3: C — Conformité | J3: C — Note (0-5) | K3: C — Commentaire | L3: Preuve / réf. offre
A4: CONTRÔLE D'ACCÈS & POLITIQUES
A5: 802.1X filaire / Wi-Fi | B5: Contrôle d'accès & politiques
A6: MAB / MAC authentication bypass | B6: Contrôle d'accès & politiques
A7: Portail captive / accès invités | B7: Contrôle d'accès & politiques
A8: Politiques dynamiques (VLAN, ACL, Quarantine) | B8: Contrôle d'accès & politiques
A9: Posture assessment (antivirus, patch, disk encrypt) | B9: Contrôle d'accès & politiques
A10: Gestion BYOD / employés / partenaires | B10: Contrôle d'accès & politiques
A11: Gestion IoT / OT / équipements non managés | B11: Contrôle d'accès & politiques
A12: PROFILAGE & VISIBILITÉ
A13: Découverte & inventaire des assets | B13: Profilage & visibilité assets
A14: Fingerprint / profiling passif & actif | B14: Profilage & visibilité assets
A15: Classification automatique des devices | B15: Profilage & visibilité assets
A16: Visibilité temps réel (qui/quoi/où) | B16: Profilage & visibilité assets
A17: INTÉGRATIONS RÉSEAU / IAM / MDM
A18: Compatibilité switches multi-vendeurs | B18: Intégrations réseau / IAM / MDM
A19: Contrôleurs Wi-Fi / WLC | B19: Intégrations réseau / IAM / MDM
A20: VPN / remote access | B20: Intégrations réseau / IAM / MDM
A21: Intégration AD / Entra ID / RADIUS / PKI | B21: Intégrations réseau / IAM / MDM
A22: Intégration MDM / EMM (Intune, etc.) | B22: Intégrations réseau / IAM / MDM
A23: Intégration SIEM / firewall / SOAR | B23: Intégrations réseau / IAM / MDM
A24: DÉPLOIEMENT & MODES
A25: Mode monitor / audit puis enforce | B25: Déploiement & modes (monitor→enforce)
A26: Complexité de déploiement (agents, appliances) | B26: Déploiement & modes (monitor→enforce)
A27: Haute disponibilité du policy server | B27: Déploiement & modes (monitor→enforce)
A28: Scalabilité multi-sites | B28: Déploiement & modes (monitor→enforce)
A29: SÉCURITÉ & SEGMENTATION
A30: Micro-segmentation / Zero Trust network access | B30: Sécurité, conformité, segmentation
A31: Quarantine / remédiation automatisée | B31: Sécurité, conformité, segmentation
A32: Traçabilité & reporting conformité | B32: Sécurité, conformité, segmentation
A33: SUPPORT, FORMATION, ROADMAP
A34: SLA support | B34: Support, formation, roadmap
A35: Formation & documentation | B35: Support, formation, roadmap
A36: Roadmap & pérennité | B36: Support, formation, roadmap
A37: Références clients | B37: Support, formation, roadmap
A38: TCO / RAPPORT QUALITÉ-PRIX
A39: Clarté du modèle de licence | B39: TCO / rapport qualité-prix
A40: Adéquation prix / périmètre | B40: TCO / rapport qualité-prix
...

Sheet 05_TCO
A1: COÛT TOTAL DE POSSESSION (TCO) — 3 ANS — € HT
A3: Poste de coût | B3: Offre A | C3: Offre B | D3: Offre C | E3: Unité / base | F3: Commentaire / hypothèses
A4: SIEM — LICENCES & ABONNEMENTS
A5: Licence / abonnement SIEM année 1 | B5: 0 | C5: 0 | D5: 0
A6: Licence / abonnement SIEM année 2 | B6: 0 | C6: 0 | D6: 0
A7: Licence / abonnement SIEM année 3 | B7: 0 | C7: 0 | D7: 0
A8: Modules optionnels (UEBA, SOAR, TI…) | B8: 0 | C8: 0 | D8: 0
A9: Stockage / rétention additionnelle | B9: 0 | C9: 0 | D9: 0
A10: Connecteurs / EPS burst / overage | B10: 0 | C10: 0 | D10: 0
A11: NAC — LICENCES & ABONNEMENTS
A12: Licence / abonnement NAC année 1 | B12: 0 | C12: 0 | D12: 0
A13: Licence / abonnement NAC année 2 | B13: 0 | C13: 0 | D13: 0
A14: Licence / abonnement NAC année 3 | B14: 0 | C14: 0 | D14: 0
A15: Licences endpoints / devices | B15: 0 | C15: 0 | D15: 0
A16: Appliances / VM / hardware | B16: 0 | C16: 0 | D16: 0
A17: Modules optionnels (guest, posture…) | B17: 0 | C17: 0 | D17: 0
A18: DÉPLOIEMENT & INTÉGRATION
A19: Prestation d'intégration SIEM | B19: 0 | C19: 0 | D19: 0
A20: Prestation d'intégration NAC | B20: 0 | C20: 0 | D20: 0
A21: Développement règles / cas d'usage | B21: 0 | C21: 0 | D21: 0
A22: Migration / reprise de l'existant | B22: 0 | C22: 0 | D22: 0
A23: Frais de projet / PMO | B23: 0 | C23: 0 | D23: 0
A24: FORMATION & ACCOMPAGNEMENT
A25: Formation administrateurs | B25: 0 | C25: 0 | D25: 0
A26: Formation analystes SOC | B26: 0 | C26: 0 | D26: 0
A27: Run / assistance au démarrage (jours) | B27: 0 | C27: 0 | D27: 0
A28: SUPPORT & MAINTENANCE
A29: Support / maintenance année 1 (si séparé) | B29: 0 | C29: 0 | D29: 0
A30: Support / maintenance année 2 | B30: 0 | C30: 0 | D30: 0
A31: Support / maintenance année 3 | B31: 0 | C31: 0 | D31: 0
A32: MSSP / co-gestion SOC (option) | B32: 0 | C32: 0 | D32: 0
A33: AUTRES
A34: Infrastructure d'hébergement (si on-prem) | B34: 0 | C34: 0 | D34: 0
A35: Réseau / certificats / PKI | B35: 0 | C35: 0 | D35: 0
A36: Divers / imprévus (ex. 5–10 %) | B36: 0 | C36: 0 | D36: 0
A37: TOTAUX
A38: TCO 3 ANS TOTAL | B38: =SUM(B5:B36) | C38: =SUM(C5:C36) | D38: =SUM(D5:D36)
A40: TCO annuel moyen | B40: =B38/3 | C40: =C38/3 | D40: =D38/3
A42: Note TCO (0–5) — à reporter dans les grilles si besoin
A43: Plus bas TCO = meilleure note (saisie manuelle ou auto ci-dessous)
...

Sheet 06_Scores
A1: SCORES PONDÉRÉS — CALCUL AUTOMATIQUE
A2: Les moyennes par famille sont calculées depuis 03_SIEM_Critères et 04_NAC_Critères. Les poids viennent de 02_Contexte. Ne modifiez que les poids / notes sources.
A4: SIEM — SCORES PAR FAMILLE
A5: Famille | B5: Poids % | C5: Moy. A | D5: Moy. B | E5: Moy. C | F5: Score pond. A | G5: Score pond. B | H5: Score pond. C
A6: Fonctionnalités & détection | B6: ='02_Contexte'!B34 | C6: =IFERROR(AVERAGEIF('03_SIEM_Critères'!$B:$B,A6,'03_SIEM_Critères'!D:D),"") | D6: =IFERROR(AVERAGEIF('03_SIEM_Critères'!$B:$B,A6,'03_SIEM_Critères'!G:G),"") | E6: =IFERROR(AVERAGEIF('03_SIEM_Critères'!$B:$B,A6,'03_SIEM_Critères'!J:J),"") | F6: =IF(C6="","",C6*B6/100) | G6: =IF(D6="","",D6*B6/100) | H6: =IF(E6="","",E6*B6/100)
A7: Architecture & performance | B7: ='02_Contexte'!B35 | C7: =IFERROR(AVERAGEIF('03_SIEM_Critères'!$B:$B,A7,'03_SIEM_Critères'!D:D),"") | D7: =IFERROR(AVERAGEIF('03_SIEM_Critères'!$B:$B,A7,'03_SIEM_Critères'!G:G),"") | E7: =IFERROR(AVERAGEIF('03_SIEM_Critères'!$B:$B,A7,'03_SIEM_Critères'!J:J),"") | F7: =IF(C7="","",C7*B7/100) | G7: =IF(D7="","",D7*B7/100) | H7: =IF(E7="","",E7*B7/100)
A8: Intégrations & écosystème | B8: ='02_Contexte'!B36 | C8: =IFERROR(AVERAGEIF('03_SIEM_Critères'!$B:$B,A8,'03_SIEM_Critères'!D:D),"") | D8: =IFERROR(AVERAGEIF('03_SIEM_Critères'!$B:$B,A8,'03_SIEM_Critères'!G:G),"") | E8: =IFERROR(AVERAGEIF('03_SIEM_Critères'!$B:$B,A8,'03_SIEM_Critères'!J:J),"") | F8: =IF(C8="","",C8*B8/100) | G8: =IF(D8="","",D8*B8/100) | H8: =IF(E8="","",E8*B8/100)
A9: Exploitation & usabilité SOC | B9: ='02_Contexte'!B37 | C9: =IFERROR(AVERAGEIF('03_SIEM_Critères'!$B:$B,A9,'03_SIEM_Critères'!D:D),"") | D9: =IFERROR(AVERAGEIF('03_SIEM_Critères'!$B:$B,A9,'03_SIEM_Critères'!G:G),"") | E9: =IFERROR(AVERAGEIF('03_SIEM_Critères'!$B:$B,A9,'03_SIEM_Critères'!J:J),"") | F9: =IF(C9="","",C9*B9/100) | G9: =IF(D9="","",D9*B9/100) | H9: =IF(E9="","",E9*B9/100)
A10: Sécurité, conformité, gouvernance | B10: ='02_Contexte'!B38 | C10: =IFERROR(AVERAGEIF('03_SIEM_Critères'!$B:$B,A10,'03_SIEM_Critères'!D:D),"") | D10: =IFERROR(AVERAGEIF('03_SIEM_Critères'!$B:$B,A10,'03_SIEM_Critères'!G:G),"") | E10: =IFERROR(AVERAGEIF('03_SIEM_Critères'!$B:$B,A10,'03_SIEM_Critères'!J:J),"") | F10: =IF(C10="","",C10*B10/100) | G10: =IF(D10="","",D10*B10/100) | H10: =IF(E10="","",E10*B10/100)
A11: Support, formation, roadmap | B11: ='02_Contexte'!B39 | C11: =IFERROR(AVERAGEIF('03_SIEM_Critères'!$B:$B,A11,'03_SIEM_Critères'!D:D),"") | D11: =IFERROR(AVERAGEIF('03_SIEM_Critères'!$B:$B,A11,'03_SIEM_Critères'!G:G),"") | E11: =IFERROR(AVERAGEIF('03_SIEM_Critères'!$B:$B,A11,'03_SIEM_Critères'!J:J),"") | F11: =IF(C11="","",C11*B11/100) | G11: =IF(D11="","",D11*B11/100) | H11: =IF(E11="","",E11*B11/100)
A12: TCO / rapport qualité-prix | B12: ='02_Contexte'!B40 | C12: =IFERROR(AVERAGEIF('03_SIEM_Critères'!$B:$B,A12,'03_SIEM_Critères'!D:D),"") | D12: =IFERROR(AVERAGEIF('03_SIEM_Critères'!$B:$B,A12,'03_SIEM_Critères'!G:G),"") | E12: =IFERROR(AVERAGEIF('03_SIEM_Critères'!$B:$B,A12,'03_SIEM_Critères'!J:J),"") | F12: =IF(C12="","",C12*B12/100) | G12: =IF(D12="","",D12*B12/100) | H12: =IF(E12="","",E12*B12/100)
A13: SCORE SIEM / 5 | B13: =SUM(B6:B12) | F13: =SUM(F6:F12) | G13: =SUM(G6:G12) | H13: =SUM(H6:H12)
A15: NAC — SCORES PAR FAMILLE
A16: Famille | B16: Poids % | C16: Moy. A | D16: Moy. B | E16: Moy. C | F16: Score pond. A | G16: Score pond. B | H16: Score pond. C
A17: Contrôle d'accès & politiques | B17: ='02_Contexte'!B46 | C17: =IFERROR(AVERAGEIF('04_NAC_Critères'!$B:$B,A17,'04_NAC_Critères'!D:D),"") | D17: =IFERROR(AVERAGEIF('04_NAC_Critères'!$B:$B,A17,'04_NAC_Critères'!G:G),"") | E17: =IFERROR(AVERAGEIF('04_NAC_Critères'!$B:$B,A17,'04_NAC_Critères'!J:J),"") | F17: =IF(C17="","",C17*B17/100) | G17: =IF(D17="","",D17*B17/100) | H17: =IF(E17="","",E17*B17/100)
A18: Profilage & visibilité assets | B18: ='02_Contexte'!B47 | C18: =IFERROR(AVERAGEIF('04_NAC_Critères'!$B:$B,A18,'04_NAC_Critères'!D:D),"") | D18: =IFERROR(AVERAGEIF('04_NAC_Critères'!$B:$B,A18,'04_NAC_Critères'!G:G),"") | E18: =IFERROR(AVERAGEIF('04_NAC_Critères'!$B:$B,A18,'04_NAC_Critères'!J:J),"") | F18: =IF(C18="","",C18*B18/100) | G18: =IF(D18="","",D18*B18/100) | H18: =IF(E18="","",E18*B18/100)
A19: Intégrations réseau / IAM / MDM | B19: ='02_Contexte'!B48 | C19: =IFERROR(AVERAGEIF('04_NAC_Critères'!$B:$B,A19,'04_NAC_Critères'!D:D),"") | D19: =IFERROR(AVERAGEIF('04_NAC_Critères'!$B:$B,A19,'04_NAC_Critères'!G:G),"") | E19: =IFERROR(AVERAGEIF('04_NAC_Critères'!$B:$B,A19,'04_NAC_Critères'!J:J),"") | F19: =IF(C19="","",C19*B19/100) | G19: =IF(D19="","",D19*B19/100) | H19: =IF(E19="","",E19*B19/100)
A20: Déploiement & modes (monitor→enforce) | B20: ='02_Contexte'!B49 | C20: =IFERROR(AVERAGEIF('04_NAC_Critères'!$B:$B,A20,'04_NAC_Critères'!D:D),"") | D20: =IFERROR(AVERAGEIF('04_NAC_Critères'!$B:$B,A20,'04_NAC_Critères'!G:G),"") | E20: =IFERROR(AVERAGEIF('04_NAC_Critères'!$B:$B,A20,'04_NAC_Critères'!J:J),"") | F20: =IF(C20="","",C20*B20/100) | G20: =IF(D20="","",D20*B20/100) | H20: =IF(E20="","",E20*B20/100)
A21: Sécurité, conformité, segmentation | B21: ='02_Contexte'!B50 | C21: =IFERROR(AVERAGEIF('04_NAC_Critères'!$B:$B,A21,'04_NAC_Critères'!D:D),"") | D21: =IFERROR(AVERAGEIF('04_NAC_Critères'!$B:$B,A21,'04_NAC_Critères'!G:G),"") | E21: =IFERROR(AVERAGEIF('04_NAC_Critères'!$B:$B,A21,'04_NAC_Critères'!J:J),"") | F21: =IF(C21="","",C21*B21/100) | G21: =IF(D21="","",D21*B21/100) | H21: =IF(E21="","",E21*B21/100)
A22: Support, formation, roadmap | B22: ='02_Contexte'!B51 | C22: =IFERROR(AVERAGEIF('04_NAC_Critères'!$B:$B,A22,'04_NAC_Critères'!D:D),"") | D22: =IFERROR(AVERAGEIF('04_NAC_Critères'!$B:$B,A22,'04_NAC_Critères'!G:G),"") | E22: =IFERROR(AVERAGEIF('04_NAC_Critères'!$B:$B,A22,'04_NAC_Critères'!J:J),"") | F22: =IF(C22="","",C22*B22/100) | G22: =IF(D22="","",D22*B22/100) | H22: =IF(E22="","",E22*B22/100)
A23: TCO / rapport qualité-prix | B23: ='02_Contexte'!B52 | C23: =IFERROR(AVERAGEIF('04_NAC_Critères'!$B:$B,A23,'04_NAC_Critères'!D:D),"") | D23: =IFERROR(AVERAGEIF('04_NAC_Critères'!$B:$B,A23,'04_NAC_Critères'!G:G),"") | E23: =IFERROR(AVERAGEIF('04_NAC_Critères'!$B:$B,A23,'04_NAC_Critères'!J:J),"") | F23: =IF(C23="","",C23*B23/100) | G23: =IF(D23="","",D23*B23/100) | H23: =IF(E23="","",E23*B23/100)
A24: SCORE NAC / 5 | B24: =SUM(B17:B23) | F24: =SUM(F17:F23) | G24: =SUM(G17:G23) | H24: =SUM(H17:H23)
A26: SCORE GLOBAL PROJET (SIEM + NAC)
A27: Composante | B27: Poids % | F27: Offre A | G27: Offre B | H27: Offre C
A28: SIEM | B28: ='02_Contexte'!B57 | F28: =F13 | G28: =G13 | H28: =H13
A29: NAC | B29: ='02_Contexte'!B58 | F29: =F24 | G29: =G24 | H29: =H24
A30: SCORE GLOBAL / 5 | F30: =(F28*B28+F29*B29)/100 | G30: =(G28*B28+G29*B29)/100 | H30: =(H28*B28+H29*B29)/100
A32: Classement (1 = meilleur) | F32: Offre A | G32: Offre B | H32: Offre C
A33: Rang | F33: =IF(F30="","",RANK(F30,$F$30:$H$30,0)) | G33: =IF(G30="","",RANK(G30,$F$30:$H$30,0)) | H33: =IF(H30="","",RANK(H30,$F$30:$H$30,0))

Sheet 07_Synthese
A1: SYNTHÈSE DÉCISIONNELLE
A3: TABLEAU DE BORD
A4: Indicateur | B4: Offre A | C4: Offre B | D4: Offre C | E4: Commentaire
A5: Éditeur / produit SIEM | B5: ='02_Contexte'!B5 | C5: ='02_Contexte'!C5 | D5: ='02_Contexte'!D5
A6: Éditeur / produit NAC | B6: ='02_Contexte'!B6 | C6: ='02_Contexte'!C6 | D6: ='02_Contexte'!D6
A7: Score SIEM / 5 | B7: ='06_Scores'!F13 | C7: ='06_Scores'!G13 | D7: ='06_Scores'!H13
A8: Score NAC / 5 | B8: ='06_Scores'!F24 | C8: ='06_Scores'!G24 | D8: ='06_Scores'!H24
A9: Score global / 5 | B9: ='06_Scores'!F30 | C9: ='06_Scores'!G30 | D9: ='06_Scores'!H30
A10: Classement | B10: ='06_Scores'!F33 | C10: ='06_Scores'!G33 | D10: ='06_Scores'!H33
A11: TCO 3 ans (€ HT) | B11: ='05_TCO'!B38 | C11: ='05_TCO'!C38 | D11: ='05_TCO'!D38
A14: ANALYSE QUALITATIVE (saisie libre)
A15: Offre | B15: Points forts | C15: Points faibles / écarts | D15: Risques | E15: Conditions suspensives
A16: Offre A
A17: Offre B
A18: Offre C
A20: RECOMMANDATION
A21: Offre recommandée
A22: Justification (5–10 lignes)
A28: Scénario alternatif / plan B
A32: Prochaines étapes (PoC, audit licence, négociation, atelier technique…)
A37: VALIDATION
A38: Rôle | B38: Nom | C38: Date | D38: Visa / décision | E38: Commentaire
A39: RSSI / Cyber
A40: DSI / Infra
A41: Achats
A42: Direction

Sheet 08_Checklist_PoC
A1: CHECKLIST PoC / PILOTE (optionnel)
A3: # | B3: Scénario de test | C3: Offre A | D3: Offre B | E3: Offre C | F3: Résultat / écart
A4: 1 | B4: Ingestion des sources de logs prioritaires
A5: 2 | B5: Création / tuning d'un cas d'usage de détection
A6: 3 | B6: Temps de recherche forensics sur 7 jours
A7: 4 | B7: Génération d'un rapport conformité
A8: 5 | B8: Intégration EDR → alerte SIEM
A9: 6 | B9: Authentification 802.1X sur switch test
A10: 7 | B10: Profilage d'un device IoT inconnu
A11: 8 | B11: Mise en quarantine automatisée
A12: 9 | B12: Portail invité + sponsoring
A13: 10 | B13: Intégration AD / certificats
A14: 11 | B14: Corrélation événement NAC → SIEM
A15: 12 | B15: Basculer monitor → enforce sans coupure
... A18: 15 | B18: Charge / performance sous volume cible
